Nov 26 07:58:42 localhost cloud-init[2066]: 2023-11-26 07:58:42,042 - url_helper.py[WARNING]: Exception(s) [UrlError("HTTPConnectionPool(host='169.254.169.254', port=80): Max retries exceeded with url: /latest/api/token (Caused by NewConnectionError('<urllib3.connection.HTTPConnection object at 0x7f62cb433ee0>: Failed to establish a new connection: [Errno 101] Network is unreachable'))"), UrlError("HTTPConnectionPool(host='fd00:ec2::254', port=80): Max retries exceeded with url: /latest/api/token (Caused by NewConnectionError('<urllib3.connection.HTTPConnection object at 0x7f62cb3ce8e0>: Failed to establish a new connection: [Errno 101] Network is unreachable'))")] during request to http://[fd00:ec2::254]:80/latest/api/token, raising last exception
Nov 26 07:58:42 localhost cloud-init[2066]: 2023-11-26 07:58:42,043 - url_helper.py[WARNING]: Calling 'None' failed [0/120s]: request error [HTTPConnectionPool(host='fd00:ec2::254', port=80): Max retries exceeded with url: /latest/api/token (Caused by NewConnectionError('<urllib3.connection.HTTPConnection object at 0x7f62cb3ce8e0>: Failed to establish a new connection: [Errno 101] Network is unreachable'))]
Nov 26 07:58:42 localhost cloud-init[2066]: 2023-11-26 07:58:42,447 - url_helper.py[WARNING]: Exception(s) [UrlError("HTTPConnectionPool(host='169.254.169.254', port=80): Max retries exceeded with url: /latest/api/token (Caused by NewConnectionError('<urllib3.connection.HTTPConnection object at 0x7f62cb3e3af0>: Failed to establish a new connection: [Errno 101] Network is unreachable'))"), UrlError("HTTPConnectionPool(host='fd00:ec2::254', port=80): Max retries exceeded with url: /latest/api/token (Caused by NewConnectionError('<urllib3.connection.HTTPConnection object at 0x7f62cb3ec640>: Failed to establish a new connection: [Errno 101] Network is unreachable'))")] during request to http://[fd00:ec2::254]:80/latest/api/token, raising last exception
Nov 26 07:58:42 localhost cloud-init[2066]: 2023-11-26 07:58:42,447 - url_helper.py[WARNING]: Calling 'None' failed [0/120s]: request error [HTTPConnectionPool(host='fd00:ec2::254', port=80): Max retries exceeded with url: /latest/api/token (Caused by NewConnectionError('<urllib3.connection.HTTPConnection object at 0x7f62cb3ec640>: Failed to establish a new connection: [Errno 101] Network is unreachable'))]
Nov 26 07:58:42 localhost cloud-init[2066]: 2023-11-26 07:58:42,851 - url_helper.py[WARNING]: Exception(s) [UrlError("HTTPConnectionPool(host='169.254.169.254', port=80): Max retries exceeded with url: /latest/api/token (Caused by NewConnectionError('<urllib3.connection.HTTPConnection object at 0x7f62cb3ec310>: Failed to establish a new connection: [Errno 101] Network is unreachable'))"), UrlError("HTTPConnectionPool(host='fd00:ec2::254', port=80): Max retries exceeded with url: /latest/api/token (Caused by NewConnectionError('<urllib3.connection.HTTPConnection object at 0x7f62cb3e3490>: Failed to establish a new connection: [Errno 101] Network is unreachable'))")] during request to http://[fd00:ec2::254]:80/latest/api/token, raising last exception
Nov 26 07:58:42 localhost cloud-init[2066]: 2023-11-26 07:58:42,851 - url_helper.py[WARNING]: Calling 'None' failed [0/120s]: request error [HTTPConnectionPool(host='fd00:ec2::254', port=80): Max retries exceeded with url: /latest/api/token (Caused by NewConnectionError('<urllib3.connection.HTTPConnection object at 0x7f62cb3e3490>: Failed to establish a new connection: [Errno 101] Network is unreachable'))]
Nov 26 07:58:43 localhost cloud-init[2066]: 2023-11-26 07:58:43,256 - url_helper.py[WARNING]: Exception(s) [UrlError("HTTPConnectionPool(host='169.254.169.254', port=80): Max retries exceeded with url: /latest/api/token (Caused by NewConnectionError('<urllib3.connection.HTTPConnection object at 0x7f62cb3f4820>: Failed to establish a new connection: [Errno 101] Network is unreachable'))"), UrlError("HTTPConnectionPool(host='fd00:ec2::254', port=80): Max retries exceeded with url: /latest/api/token (Caused by NewConnectionError('<urllib3.connection.HTTPConnection object at 0x7f62cb380370>: Failed to establish a new connection: [Errno 101] Network is unreachable'))")] during request to http://[fd00:ec2::254]:80/latest/api/token, raising last exception
Nov 26 07:58:43 localhost cloud-init[2066]: 2023-11-26 07:58:43,256 - url_helper.py[WARNING]: Calling 'None' failed [1/120s]: request error [HTTPConnectionPool(host='fd00:ec2::254', port=80): Max retries exceeded with url: /latest/api/token (Caused by NewConnectionError('<urllib3.connection.HTTPConnection object at 0x7f62cb380370>: Failed to establish a new connection: [Errno 101] Network is unreachable'))]
Nov 26 07:58:43 localhost cloud-init[2066]: 2023-11-26 07:58:43,660 - url_helper.py[WARNING]: Exception(s) [UrlError("HTTPConnectionPool(host='169.254.169.254', port=80): Max retries exceeded with url: /latest/api/token (Caused by NewConnectionError('<urllib3.connection.HTTPConnection object at 0x7f62cb3f45e0>: Failed to establish a new connection: [Errno 101] Network is unreachable'))"), UrlError("HTTPConnectionPool(host='fd00:ec2::254', port=80): Max retries exceeded with url: /latest/api/token (Caused by NewConnectionError('<urllib3.connection.HTTPConnection object at 0x7f62cb3eccd0>: Failed to establish a new connection: [Errno 101] Network is unreachable'))")] during request to http://[fd00:ec2::254]:80/latest/api/token, raising last exception
Nov 26 07:58:43 localhost cloud-init[2066]: 2023-11-26 07:58:43,660 - url_helper.py[WARNING]: Calling 'None' failed [1/120s]: request error [HTTPConnectionPool(host='fd00:ec2::254', port=80): Max retries exceeded with url: /latest/api/token (Caused by NewConnectionError('<urllib3.connection.HTTPConnection object at 0x7f62cb3eccd0>: Failed to establish a new connection: [Errno 101] Network is unreachable'))]
Nov 26 07:58:44 localhost cloud-init[2066]: 2023-11-26 07:58:44,064 - url_helper.py[WARNING]: Exception(s) [UrlError("HTTPConnectionPool(host='169.254.169.254', port=80): Max retries exceeded with url: /latest/api/token (Caused by NewConnectionError('<urllib3.connection.HTTPConnection object at 0x7f62cb386550>: Failed to establish a new connection: [Errno 101] Network is unreachable'))"), UrlError("HTTPConnectionPool(host='fd00:ec2::254', port=80): Max retries exceeded with url: /latest/api/token (Caused by NewConnectionError('<urllib3.connection.HTTPConnection object at 0x7f62cb3930a0>: Failed to establish a new connection: [Errno 101] Network is unreachable'))")] during request to http://[fd00:ec2::254]:80/latest/api/token, raising last exception
Nov 26 07:58:44 localhost cloud-init[2066]: 2023-11-26 07:58:44,064 - url_helper.py[WARNING]: Calling 'None' failed [2/120s]: request error [HTTPConnectionPool(host='fd00:ec2::254', port=80): Max retries exceeded with url: /latest/api/token (Caused by NewConnectionError('<urllib3.connection.HTTPConnection object at 0x7f62cb3930a0>: Failed to establish a new connection: [Errno 101] Network is unreachable'))]
Nov 26 07:58:45 localhost cloud-init[2066]: 2023-11-26 07:58:45,470 - url_helper.py[WARNING]: Exception(s) [UrlError("HTTPConnectionPool(host='169.254.169.254', port=80): Max retries exceeded with url: /latest/api/token (Caused by NewConnectionError('<urllib3.connection.HTTPConnection object at 0x7f62cb399280>: Failed to establish a new connection: [Errno 101] Network is unreachable'))"), UrlError("HTTPConnectionPool(host='fd00:ec2::254', port=80): Max retries exceeded with url: /latest/api/token (Caused by NewConnectionError('<urllib3.connection.HTTPConnection object at 0x7f62cb399d90>: Failed to establish a new connection: [Errno 101] Network is unreachable'))")] during request to http://[fd00:ec2::254]:80/latest/api/token, raising last exception
Nov 26 07:58:45 localhost cloud-init[2066]: 2023-11-26 07:58:45,470 - url_helper.py[WARNING]: Calling 'None' failed [3/120s]: request error [HTTPConnectionPool(host='fd00:ec2::254', port=80): Max retries exceeded with url: /latest/api/token (Caused by NewConnectionError('<urllib3.connection.HTTPConnection object at 0x7f62cb399d90>: Failed to establish a new connection: [Errno 101] Network is unreachable'))]
Nov 26 07:58:47 localhost cloud-init[2066]: 2023-11-26 07:58:47,876 - url_helper.py[WARNING]: Exception(s) [UrlError("HTTPConnectionPool(host='169.254.169.254', port=80): Max retries exceeded with url: /latest/api/token (Caused by NewConnectionError('<urllib3.connection.HTTPConnection object at 0x7f62cb399e20>: Failed to establish a new connection: [Errno 101] Network is unreachable'))"), UrlError("HTTPConnectionPool(host='fd00:ec2::254', port=80): Max retries exceeded with url: /latest/api/token (Caused by NewConnectionError('<urllib3.connection.HTTPConnection object at 0x7f62cb393dc0>: Failed to establish a new connection: [Errno 101] Network is unreachable'))")] during request to http://[fd00:ec2::254]:80/latest/api/token, raising last exception
Nov 26 07:58:47 localhost cloud-init[2066]: 2023-11-26 07:58:47,876 - url_helper.py[WARNING]: Calling 'None' failed [6/120s]: request error [HTTPConnectionPool(host='fd00:ec2::254', port=80): Max retries exceeded with url: /latest/api/token (Caused by NewConnectionError('<urllib3.connection.HTTPConnection object at 0x7f62cb393dc0>: Failed to establish a new connection: [Errno 101] Network is unreachable'))]
Nov 26 07:58:51 localhost cloud-init[2066]: 2023-11-26 07:58:51,283 - url_helper.py[WARNING]: Exception(s) [UrlError("HTTPConnectionPool(host='169.254.169.254', port=80): Max retries exceeded with url: /latest/api/token (Caused by NewConnectionError('<urllib3.connection.HTTPConnection object at 0x7f62cb3a7f70>: Failed to establish a new connection: [Errno 101] Network is unreachable'))"), UrlError("HTTPConnectionPool(host='fd00:ec2::254', port=80): Max retries exceeded with url: /latest/api/token (Caused by NewConnectionError('<urllib3.connection.HTTPConnection object at 0x7f62cb3adac0>: Failed to establish a new connection: [Errno 101] Network is unreachable'))")] during request to http://[fd00:ec2::254]:80/latest/api/token, raising last exception
Nov 26 07:58:51 localhost cloud-init[2066]: 2023-11-26 07:58:51,284 - url_helper.py[WARNING]: Calling 'None' failed [9/120s]: request error [HTTPConnectionPool(host='fd00:ec2::254', port=80): Max retries exceeded with url: /latest/api/token (Caused by NewConnectionError('<urllib3.connection.HTTPConnection object at 0x7f62cb3adac0>: Failed to establish a new connection: [Errno 101] Network is unreachable'))]
Nov 26 07:58:55 localhost cloud-init[2066]: 2023-11-26 07:58:55,693 - url_helper.py[WARNING]: Exception(s) [UrlError("HTTPConnectionPool(host='169.254.169.254', port=80): Max retries exceeded with url: /latest/api/token (Caused by NewConnectionError('<urllib3.connection.HTTPConnection object at 0x7f62cb3ad730>: Failed to establish a new connection: [Errno 101] Network is unreachable'))"), UrlError("HTTPConnectionPool(host='fd00:ec2::254', port=80): Max retries exceeded with url: /latest/api/token (Caused by NewConnectionError('<urllib3.connection.HTTPConnection object at 0x7f62cb3a7c70>: Failed to establish a new connection: [Errno 101] Network is unreachable'))")] during request to http://[fd00:ec2::254]:80/latest/api/token, raising last exception
Nov 26 07:58:55 localhost cloud-init[2066]: 2023-11-26 07:58:55,693 - url_helper.py[WARNING]: Calling 'None' failed [13/120s]: request error [HTTPConnectionPool(host='fd00:ec2::254', port=80): Max retries exceeded with url: /latest/api/token (Caused by NewConnectionError('<urllib3.connection.HTTPConnection object at 0x7f62cb3a7c70>: Failed to establish a new connection: [Errno 101] Network is unreachable'))]
Nov 26 07:59:01 localhost cloud-init[2066]: 2023-11-26 07:59:01,102 - url_helper.py[WARNING]: Exception(s) [UrlError("HTTPConnectionPool(host='169.254.169.254', port=80): Max retries exceeded with url: /latest/api/token (Caused by NewConnectionError('<urllib3.connection.HTTPConnection object at 0x7f62cb399a00>: Failed to establish a new connection: [Errno 101] Network is unreachable'))"), UrlError("HTTPConnectionPool(host='fd00:ec2::254', port=80): Max retries exceeded with url: /latest/api/token (Caused by NewConnectionError('<urllib3.connection.HTTPConnection object at 0x7f62cb393d00>: Failed to establish a new connection: [Errno 101] Network is unreachable'))")] during request to http://[fd00:ec2::254]:80/latest/api/token, raising last exception
Nov 26 07:59:01 localhost cloud-init[2066]: 2023-11-26 07:59:01,102 - url_helper.py[WARNING]: Calling 'None' failed [19/120s]: request error [HTTPConnectionPool(host='fd00:ec2::254', port=80): Max retries exceeded with url: /latest/api/token (Caused by NewConnectionError('<urllib3.connection.HTTPConnection object at 0x7f62cb393d00>: Failed to establish a new connection: [Errno 101] Network is unreachable'))]
Nov 26 07:59:08 localhost cloud-init[2066]: 2023-11-26 07:59:08,514 - url_helper.py[WARNING]: Exception(s) [UrlError("HTTPConnectionPool(host='169.254.169.254', port=80): Max retries exceeded with url: /latest/api/token (Caused by NewConnectionError('<urllib3.connection.HTTPConnection object at 0x7f62cb393ac0>: Failed to establish a new connection: [Errno 101] Network is unreachable'))"), UrlError("HTTPConnectionPool(host='fd00:ec2::254', port=80): Max retries exceeded with url: /latest/api/token (Caused by NewConnectionError('<urllib3.connection.HTTPConnection object at 0x7f62cb399ca0>: Failed to establish a new connection: [Errno 101] Network is unreachable'))")] during request to http://[fd00:ec2::254]:80/latest/api/token, raising last exception
Nov 26 07:59:08 localhost cloud-init[2066]: 2023-11-26 07:59:08,631 - url_helper.py[WARNING]: Calling 'None' failed [26/120s]: request error [HTTPConnectionPool(host='fd00:ec2::254', port=80): Max retries exceeded with url: /latest/api/token (Caused by NewConnectionError('<urllib3.connection.HTTPConnection object at 0x7f62cb399ca0>: Failed to establish a new connection: [Errno 101] Network is unreachable'))]
