Nov 26 07:58:34 localhost kernel: acpi PNP0A03:00: fail to add MMCONFIG information, can't access extended PCI configuration space under this bridge.
Nov 26 07:58:34 localhost rngd[300]: [hwrng ]: Initialization Failed
Nov 26 07:58:38 localhost systemd[1]: Failed to open libbpf, cgroup BPF features disabled: Operation not supported
Nov 26 07:58:39 localhost rngd[1922]: [hwrng ]: Initialization Failed
Nov 26 07:58:42 localhost cloud-init[2066]: 2023-11-26 07:58:42,042 - url_helper.py[WARNING]: Exception(s) [UrlError("HTTPConnectionPool(host='169.254.169.254', port=80): Max retries exceeded with url: /latest/api/token (Caused by NewConnectionError('<urllib3.connection.HTTPConnection object at 0x7f62cb433ee0>: Failed to establish a new connection: [Errno 101] Network is unreachable'))"), UrlError("HTTPConnectionPool(host='fd00:ec2::254', port=80): Max retries exceeded with url: /latest/api/token (Caused by NewConnectionError('<urllib3.connection.HTTPConnection object at 0x7f62cb3ce8e0>: Failed to establish a new connection: [Errno 101] Network is unreachable'))")] during request to http://[fd00:ec2::254]:80/latest/api/token, raising last exception
Nov 26 07:58:42 localhost cloud-init[2066]: 2023-11-26 07:58:42,043 - url_helper.py[WARNING]: Calling 'None' failed [0/120s]: request error [HTTPConnectionPool(host='fd00:ec2::254', port=80): Max retries exceeded with url: /latest/api/token (Caused by NewConnectionError('<urllib3.connection.HTTPConnection object at 0x7f62cb3ce8e0>: Failed to establish a new connection: [Errno 101] Network is unreachable'))]
Nov 26 07:58:42 localhost cloud-init[2066]: 2023-11-26 07:58:42,447 - url_helper.py[WARNING]: Exception(s) [UrlError("HTTPConnectionPool(host='169.254.169.254', port=80): Max retries exceeded with url: /latest/api/token (Caused by NewConnectionError('<urllib3.connection.HTTPConnection object at 0x7f62cb3e3af0>: Failed to establish a new connection: [Errno 101] Network is unreachable'))"), UrlError("HTTPConnectionPool(host='fd00:ec2::254', port=80): Max retries exceeded with url: /latest/api/token (Caused by NewConnectionError('<urllib3.connection.HTTPConnection object at 0x7f62cb3ec640>: Failed to establish a new connection: [Errno 101] Network is unreachable'))")] during request to http://[fd00:ec2::254]:80/latest/api/token, raising last exception
Nov 26 07:58:42 localhost cloud-init[2066]: 2023-11-26 07:58:42,447 - url_helper.py[WARNING]: Calling 'None' failed [0/120s]: request error [HTTPConnectionPool(host='fd00:ec2::254', port=80): Max retries exceeded with url: /latest/api/token (Caused by NewConnectionError('<urllib3.connection.HTTPConnection object at 0x7f62cb3ec640>: Failed to establish a new connection: [Errno 101] Network is unreachable'))]
Nov 26 07:58:42 localhost cloud-init[2066]: 2023-11-26 07:58:42,851 - url_helper.py[WARNING]: Exception(s) [UrlError("HTTPConnectionPool(host='169.254.169.254', port=80): Max retries exceeded with url: /latest/api/token (Caused by NewConnectionError('<urllib3.connection.HTTPConnection object at 0x7f62cb3ec310>: Failed to establish a new connection: [Errno 101] Network is unreachable'))"), UrlError("HTTPConnectionPool(host='fd00:ec2::254', port=80): Max retries exceeded with url: /latest/api/token (Caused by NewConnectionError('<urllib3.connection.HTTPConnection object at 0x7f62cb3e3490>: Failed to establish a new connection: [Errno 101] Network is unreachable'))")] during request to http://[fd00:ec2::254]:80/latest/api/token, raising last exception
Nov 26 07:58:42 localhost cloud-init[2066]: 2023-11-26 07:58:42,851 - url_helper.py[WARNING]: Calling 'None' failed [0/120s]: request error [HTTPConnectionPool(host='fd00:ec2::254', port=80): Max retries exceeded with url: /latest/api/token (Caused by NewConnectionError('<urllib3.connection.HTTPConnection object at 0x7f62cb3e3490>: Failed to establish a new connection: [Errno 101] Network is unreachable'))]
Nov 26 07:58:43 localhost cloud-init[2066]: 2023-11-26 07:58:43,256 - url_helper.py[WARNING]: Exception(s) [UrlError("HTTPConnectionPool(host='169.254.169.254', port=80): Max retries exceeded with url: /latest/api/token (Caused by NewConnectionError('<urllib3.connection.HTTPConnection object at 0x7f62cb3f4820>: Failed to establish a new connection: [Errno 101] Network is unreachable'))"), UrlError("HTTPConnectionPool(host='fd00:ec2::254', port=80): Max retries exceeded with url: /latest/api/token (Caused by NewConnectionError('<urllib3.connection.HTTPConnection object at 0x7f62cb380370>: Failed to establish a new connection: [Errno 101] Network is unreachable'))")] during request to http://[fd00:ec2::254]:80/latest/api/token, raising last exception
Nov 26 07:58:43 localhost cloud-init[2066]: 2023-11-26 07:58:43,256 - url_helper.py[WARNING]: Calling 'None' failed [1/120s]: request error [HTTPConnectionPool(host='fd00:ec2::254', port=80): Max retries exceeded with url: /latest/api/token (Caused by NewConnectionError('<urllib3.connection.HTTPConnection object at 0x7f62cb380370>: Failed to establish a new connection: [Errno 101] Network is unreachable'))]
Nov 26 07:58:43 localhost cloud-init[2066]: 2023-11-26 07:58:43,660 - url_helper.py[WARNING]: Exception(s) [UrlError("HTTPConnectionPool(host='169.254.169.254', port=80): Max retries exceeded with url: /latest/api/token (Caused by NewConnectionError('<urllib3.connection.HTTPConnection object at 0x7f62cb3f45e0>: Failed to establish a new connection: [Errno 101] Network is unreachable'))"), UrlError("HTTPConnectionPool(host='fd00:ec2::254', port=80): Max retries exceeded with url: /latest/api/token (Caused by NewConnectionError('<urllib3.connection.HTTPConnection object at 0x7f62cb3eccd0>: Failed to establish a new connection: [Errno 101] Network is unreachable'))")] during request to http://[fd00:ec2::254]:80/latest/api/token, raising last exception
Nov 26 07:58:43 localhost cloud-init[2066]: 2023-11-26 07:58:43,660 - url_helper.py[WARNING]: Calling 'None' failed [1/120s]: request error [HTTPConnectionPool(host='fd00:ec2::254', port=80): Max retries exceeded with url: /latest/api/token (Caused by NewConnectionError('<urllib3.connection.HTTPConnection object at 0x7f62cb3eccd0>: Failed to establish a new connection: [Errno 101] Network is unreachable'))]
Nov 26 07:58:44 localhost cloud-init[2066]: 2023-11-26 07:58:44,064 - url_helper.py[WARNING]: Exception(s) [UrlError("HTTPConnectionPool(host='169.254.169.254', port=80): Max retries exceeded with url: /latest/api/token (Caused by NewConnectionError('<urllib3.connection.HTTPConnection object at 0x7f62cb386550>: Failed to establish a new connection: [Errno 101] Network is unreachable'))"), UrlError("HTTPConnectionPool(host='fd00:ec2::254', port=80): Max retries exceeded with url: /latest/api/token (Caused by NewConnectionError('<urllib3.connection.HTTPConnection object at 0x7f62cb3930a0>: Failed to establish a new connection: [Errno 101] Network is unreachable'))")] during request to http://[fd00:ec2::254]:80/latest/api/token, raising last exception
Nov 26 07:58:44 localhost cloud-init[2066]: 2023-11-26 07:58:44,064 - url_helper.py[WARNING]: Calling 'None' failed [2/120s]: request error [HTTPConnectionPool(host='fd00:ec2::254', port=80): Max retries exceeded with url: /latest/api/token (Caused by NewConnectionError('<urllib3.connection.HTTPConnection object at 0x7f62cb3930a0>: Failed to establish a new connection: [Errno 101] Network is unreachable'))]
Nov 26 07:58:45 localhost cloud-init[2066]: 2023-11-26 07:58:45,470 - url_helper.py[WARNING]: Exception(s) [UrlError("HTTPConnectionPool(host='169.254.169.254', port=80): Max retries exceeded with url: /latest/api/token (Caused by NewConnectionError('<urllib3.connection.HTTPConnection object at 0x7f62cb399280>: Failed to establish a new connection: [Errno 101] Network is unreachable'))"), UrlError("HTTPConnectionPool(host='fd00:ec2::254', port=80): Max retries exceeded with url: /latest/api/token (Caused by NewConnectionError('<urllib3.connection.HTTPConnection object at 0x7f62cb399d90>: Failed to establish a new connection: [Errno 101] Network is unreachable'))")] during request to http://[fd00:ec2::254]:80/latest/api/token, raising last exception
Nov 26 07:58:45 localhost cloud-init[2066]: 2023-11-26 07:58:45,470 - url_helper.py[WARNING]: Calling 'None' failed [3/120s]: request error [HTTPConnectionPool(host='fd00:ec2::254', port=80): Max retries exceeded with url: /latest/api/token (Caused by NewConnectionError('<urllib3.connection.HTTPConnection object at 0x7f62cb399d90>: Failed to establish a new connection: [Errno 101] Network is unreachable'))]
Nov 26 07:58:47 localhost cloud-init[2066]: 2023-11-26 07:58:47,876 - url_helper.py[WARNING]: Exception(s) [UrlError("HTTPConnectionPool(host='169.254.169.254', port=80): Max retries exceeded with url: /latest/api/token (Caused by NewConnectionError('<urllib3.connection.HTTPConnection object at 0x7f62cb399e20>: Failed to establish a new connection: [Errno 101] Network is unreachable'))"), UrlError("HTTPConnectionPool(host='fd00:ec2::254', port=80): Max retries exceeded with url: /latest/api/token (Caused by NewConnectionError('<urllib3.connection.HTTPConnection object at 0x7f62cb393dc0>: Failed to establish a new connection: [Errno 101] Network is unreachable'))")] during request to http://[fd00:ec2::254]:80/latest/api/token, raising last exception
Nov 26 07:58:47 localhost cloud-init[2066]: 2023-11-26 07:58:47,876 - url_helper.py[WARNING]: Calling 'None' failed [6/120s]: request error [HTTPConnectionPool(host='fd00:ec2::254', port=80): Max retries exceeded with url: /latest/api/token (Caused by NewConnectionError('<urllib3.connection.HTTPConnection object at 0x7f62cb393dc0>: Failed to establish a new connection: [Errno 101] Network is unreachable'))]
Nov 26 07:58:51 localhost cloud-init[2066]: 2023-11-26 07:58:51,283 - url_helper.py[WARNING]: Exception(s) [UrlError("HTTPConnectionPool(host='169.254.169.254', port=80): Max retries exceeded with url: /latest/api/token (Caused by NewConnectionError('<urllib3.connection.HTTPConnection object at 0x7f62cb3a7f70>: Failed to establish a new connection: [Errno 101] Network is unreachable'))"), UrlError("HTTPConnectionPool(host='fd00:ec2::254', port=80): Max retries exceeded with url: /latest/api/token (Caused by NewConnectionError('<urllib3.connection.HTTPConnection object at 0x7f62cb3adac0>: Failed to establish a new connection: [Errno 101] Network is unreachable'))")] during request to http://[fd00:ec2::254]:80/latest/api/token, raising last exception
Nov 26 07:58:51 localhost cloud-init[2066]: 2023-11-26 07:58:51,284 - url_helper.py[WARNING]: Calling 'None' failed [9/120s]: request error [HTTPConnectionPool(host='fd00:ec2::254', port=80): Max retries exceeded with url: /latest/api/token (Caused by NewConnectionError('<urllib3.connection.HTTPConnection object at 0x7f62cb3adac0>: Failed to establish a new connection: [Errno 101] Network is unreachable'))]
Nov 26 07:58:55 localhost cloud-init[2066]: 2023-11-26 07:58:55,693 - url_helper.py[WARNING]: Exception(s) [UrlError("HTTPConnectionPool(host='169.254.169.254', port=80): Max retries exceeded with url: /latest/api/token (Caused by NewConnectionError('<urllib3.connection.HTTPConnection object at 0x7f62cb3ad730>: Failed to establish a new connection: [Errno 101] Network is unreachable'))"), UrlError("HTTPConnectionPool(host='fd00:ec2::254', port=80): Max retries exceeded with url: /latest/api/token (Caused by NewConnectionError('<urllib3.connection.HTTPConnection object at 0x7f62cb3a7c70>: Failed to establish a new connection: [Errno 101] Network is unreachable'))")] during request to http://[fd00:ec2::254]:80/latest/api/token, raising last exception
Nov 26 07:58:55 localhost cloud-init[2066]: 2023-11-26 07:58:55,693 - url_helper.py[WARNING]: Calling 'None' failed [13/120s]: request error [HTTPConnectionPool(host='fd00:ec2::254', port=80): Max retries exceeded with url: /latest/api/token (Caused by NewConnectionError('<urllib3.connection.HTTPConnection object at 0x7f62cb3a7c70>: Failed to establish a new connection: [Errno 101] Network is unreachable'))]
Nov 26 07:59:01 localhost cloud-init[2066]: 2023-11-26 07:59:01,102 - url_helper.py[WARNING]: Exception(s) [UrlError("HTTPConnectionPool(host='169.254.169.254', port=80): Max retries exceeded with url: /latest/api/token (Caused by NewConnectionError('<urllib3.connection.HTTPConnection object at 0x7f62cb399a00>: Failed to establish a new connection: [Errno 101] Network is unreachable'))"), UrlError("HTTPConnectionPool(host='fd00:ec2::254', port=80): Max retries exceeded with url: /latest/api/token (Caused by NewConnectionError('<urllib3.connection.HTTPConnection object at 0x7f62cb393d00>: Failed to establish a new connection: [Errno 101] Network is unreachable'))")] during request to http://[fd00:ec2::254]:80/latest/api/token, raising last exception
Nov 26 07:59:01 localhost cloud-init[2066]: 2023-11-26 07:59:01,102 - url_helper.py[WARNING]: Calling 'None' failed [19/120s]: request error [HTTPConnectionPool(host='fd00:ec2::254', port=80): Max retries exceeded with url: /latest/api/token (Caused by NewConnectionError('<urllib3.connection.HTTPConnection object at 0x7f62cb393d00>: Failed to establish a new connection: [Errno 101] Network is unreachable'))]
Nov 26 07:59:08 localhost cloud-init[2066]: 2023-11-26 07:59:08,514 - url_helper.py[WARNING]: Exception(s) [UrlError("HTTPConnectionPool(host='169.254.169.254', port=80): Max retries exceeded with url: /latest/api/token (Caused by NewConnectionError('<urllib3.connection.HTTPConnection object at 0x7f62cb393ac0>: Failed to establish a new connection: [Errno 101] Network is unreachable'))"), UrlError("HTTPConnectionPool(host='fd00:ec2::254', port=80): Max retries exceeded with url: /latest/api/token (Caused by NewConnectionError('<urllib3.connection.HTTPConnection object at 0x7f62cb399ca0>: Failed to establish a new connection: [Errno 101] Network is unreachable'))")] during request to http://[fd00:ec2::254]:80/latest/api/token, raising last exception
Nov 26 07:59:08 localhost cloud-init[2066]: 2023-11-26 07:59:08,631 - url_helper.py[WARNING]: Calling 'None' failed [26/120s]: request error [HTTPConnectionPool(host='fd00:ec2::254', port=80): Max retries exceeded with url: /latest/api/token (Caused by NewConnectionError('<urllib3.connection.HTTPConnection object at 0x7f62cb399ca0>: Failed to establish a new connection: [Errno 101] Network is unreachable'))]
Nov 26 07:59:21 ip-172-31-25-7.ec2.internal audit[2285]: CRED_ACQ pid=2285 uid=0 auid=4294967295 ses=4294967295 subj=system_u:system_r:init_t:s0 msg='op=PAM:setcred grantors=? acct="root" exe="/usr/lib/systemd/systemd" hostname=? addr=? terminal=? res=failed'
Nov 26 07:59:21 ip-172-31-25-7.ec2.internal systemd[2285]: Failed to open libbpf, cgroup BPF features disabled: Operation not supported
Nov 26 07:59:44 ip-172-31-25-7.ec2.internal audit[2287]: CRED_DISP pid=2287 uid=0 auid=0 ses=1 subj=system_u:system_r:init_t:s0 msg='op=PAM:setcred grantors=? acct="root" exe="/usr/lib/systemd/systemd" hostname=? addr=? terminal=? res=failed'
Nov 26 08:00:11 ip-172-31-25-7.ec2.internal audit[10677]: USER_AUTH pid=10677 uid=0 auid=4294967295 ses=4294967295 subj=system_u:system_r:sshd_t:s0-s0:c0.c1023 msg='op=pubkey acct="ec2-user" exe="/usr/sbin/sshd" hostname=? addr=122.171.94.228 terminal=ssh res=failed'
Nov 26 08:00:11 ip-172-31-25-7.ec2.internal audit[10677]: USER_ERR pid=10677 uid=0 auid=4294967295 ses=4294967295 subj=system_u:system_r:sshd_t:s0-s0:c0.c1023 msg='op=PAM:bad_ident grantors=? acct="?" exe="/usr/sbin/sshd" hostname=122.171.94.228 addr=122.171.94.228 terminal=ssh res=failed'
Nov 26 08:00:11 ip-172-31-25-7.ec2.internal audit[10677]: USER_LOGIN pid=10677 uid=0 auid=4294967295 ses=4294967295 subj=system_u:system_r:sshd_t:s0-s0:c0.c1023 msg='op=login acct="ec2-user" exe="/usr/sbin/sshd" hostname=? addr=122.171.94.228 terminal=ssh res=failed'
Nov 26 08:01:01 ip-172-31-25-7.ec2.internal systemd[1]: run-credentials-systemd\x2dtmpfiles\x2dsetup.service.mount: Failed with result 'exit-code'.
Nov 26 13:16:51 localhost kernel: acpi PNP0A03:00: fail to add MMCONFIG information, can't access extended PCI configuration space under this bridge.
Nov 26 13:16:51 localhost rngd[301]: [hwrng ]: Initialization Failed
Nov 26 13:16:55 ip-172-31-25-7.ec2.internal systemd[1]: Failed to open libbpf, cgroup BPF features disabled: Operation not supported
Nov 26 13:16:58 ip-172-31-25-7.ec2.internal rngd[1911]: [hwrng ]: Initialization Failed
Nov 26 13:32:34 ip-172-31-25-7.ec2.internal audit[2935]: USER_AUTH pid=2935 uid=0 auid=4294967295 ses=4294967295 subj=system_u:system_r:sshd_t:s0-s0:c0.c1023 msg='op=pubkey acct="ec2-user" exe="/usr/sbin/sshd" hostname=? addr=171.61.99.252 terminal=ssh res=failed'
Nov 26 13:32:35 ip-172-31-25-7.ec2.internal audit[2935]: USER_ERR pid=2935 uid=0 auid=4294967295 ses=4294967295 subj=system_u:system_r:sshd_t:s0-s0:c0.c1023 msg='op=PAM:bad_ident grantors=? acct="?" exe="/usr/sbin/sshd" hostname=171.61.99.252 addr=171.61.99.252 terminal=ssh res=failed'
Nov 26 13:32:35 ip-172-31-25-7.ec2.internal audit[2935]: USER_LOGIN pid=2935 uid=0 auid=4294967295 ses=4294967295 subj=system_u:system_r:sshd_t:s0-s0:c0.c1023 msg='op=login acct="ec2-user" exe="/usr/sbin/sshd" hostname=? addr=171.61.99.252 terminal=ssh res=failed'
Nov 26 13:46:34 ip-172-31-25-7.ec2.internal audit[3544]: USER_ERR pid=3544 uid=0 auid=4294967295 ses=4294967295 subj=system_u:system_r:sshd_t:s0-s0:c0.c1023 msg='op=PAM:bad_ident grantors=? acct="?" exe="/usr/sbin/sshd" hostname=8.218.235.111 addr=8.218.235.111 terminal=ssh res=failed'
Nov 26 13:46:34 ip-172-31-25-7.ec2.internal audit[3544]: USER_LOGIN pid=3544 uid=0 auid=4294967295 ses=4294967295 subj=system_u:system_r:sshd_t:s0-s0:c0.c1023 msg='op=login acct="(unknown)" exe="/usr/sbin/sshd" hostname=? addr=8.218.235.111 terminal=ssh res=failed'
Nov 26 13:49:15 ip-172-31-25-7.ec2.internal audit[3639]: USER_LOGIN pid=3639 uid=0 auid=4294967295 ses=4294967295 subj=system_u:system_r:sshd_t:s0-s0:c0.c1023 msg='op=login acct="(unknown)" exe="/usr/sbin/sshd" hostname=? addr=162.142.125.214 terminal=ssh res=failed'
Nov 26 13:56:20 ip-172-31-25-7.ec2.internal audit[3921]: USER_AUTH pid=3921 uid=0 auid=4294967295 ses=4294967295 subj=system_u:system_r:sshd_t:s0-s0:c0.c1023 msg='op=pubkey acct="ec2-user" exe="/usr/sbin/sshd" hostname=? addr=171.61.99.252 terminal=ssh res=failed'
Nov 26 13:56:20 ip-172-31-25-7.ec2.internal audit[3921]: USER_ERR pid=3921 uid=0 auid=4294967295 ses=4294967295 subj=system_u:system_r:sshd_t:s0-s0:c0.c1023 msg='op=PAM:bad_ident grantors=? acct="?" exe="/usr/sbin/sshd" hostname=171.61.99.252 addr=171.61.99.252 terminal=ssh res=failed'
Nov 26 13:56:20 ip-172-31-25-7.ec2.internal audit[3921]: USER_LOGIN pid=3921 uid=0 auid=4294967295 ses=4294967295 subj=system_u:system_r:sshd_t:s0-s0:c0.c1023 msg='op=login acct="ec2-user" exe="/usr/sbin/sshd" hostname=? addr=171.61.99.252 terminal=ssh res=failed'
Nov 26 13:57:53 ip-172-31-25-7.ec2.internal audit[4024]: CRED_ACQ pid=4024 uid=0 auid=4294967295 ses=4294967295 subj=system_u:system_r:init_t:s0 msg='op=PAM:setcred grantors=? acct="ec2-user" exe="/usr/lib/systemd/systemd" hostname=? addr=? terminal=? res=failed'
Nov 26 13:57:53 ip-172-31-25-7.ec2.internal systemd[4024]: Failed to open libbpf, cgroup BPF features disabled: Operation not supported
